<mujoco model="me5406_arm">
  <compiler angle="radian" autolimits="true"/>
  <option gravity="0 0 0" timestep="0.01" integrator="RK4"/>

  <default>
    <joint damping="1.0" armature="0.02" limited="true"/>
    <geom type="capsule" size="0.025" rgba="0.55 0.58 0.64 1"/>
    <motor ctrllimited="true" ctrlrange="-1 1"/>
  </default>

  <worldbody>
    <light pos="0 0 2"/>
    <geom type="plane" size="2 2 0.1" rgba="0.95 0.95 0.95 1"/>

    <body name="base" pos="0 0 0">
      <geom type="cylinder" size="0.08 0.05" rgba="0.12 0.12 0.14 1"/>

      <body name="shoulder_yaw" pos="0 0 0.14">
        <joint name="joint1" type="hinge" axis="0 0 1" range="-3.14 3.14"/>
        <geom type="cylinder" size="0.055 0.09" rgba="0.2 0.22 0.26 1"/>
        <geom type="sphere" pos="0 0 0.09" size="0.045" rgba="0.18 0.2 0.24 1"/>

        <body name="shoulder_link" pos="0 0 0.09">
          <geom type="capsule" fromto="0 0 0 0.08 0 0" size="0.03" rgba="0.45 0.47 0.54 1"/>

          <body name="upper_arm" pos="0.08 0 0">
            <joint name="joint2" type="hinge" axis="0 1 0" range="-1.7 1.2"/>
            <geom type="sphere" size="0.04" rgba="0.78 0.48 0.22 1"/>
            <geom name="link1_geom" fromto="0 0 0 0.34 0 0" size="0.028" rgba="0.78 0.48 0.22 1"/>

            <body name="forearm" pos="0.34 0 0">
              <joint name="joint3" type="hinge" axis="0 1 0" range="-2.2 1.2"/>
              <geom type="sphere" size="0.036" rgba="0.16 0.62 0.56 1"/>
              <geom name="link2_geom" fromto="0 0 0 0.30 0 0" size="0.024" rgba="0.16 0.62 0.56 1"/>

              <body name="ee" pos="0.30 0 0">
                <geom name="ee_geom" type="sphere" size="0.025" rgba="0.12 0.7 0.18 1"/>
                <site name="ee_site" pos="0 0 0" size="0.02" rgba="0.1 0.8 0.1 1"/>
              </body>
            </body>
          </body>
        </body>
      </body>
    </body>

    <body name="target" pos="0.55 0 0.15" mocap="true">
      <geom name="target_geom" type="sphere" size="0.035" contype="0" conaffinity="0" rgba="0.1 0.3 0.9 0.5"/>
      <site name="target_site" pos="0 0 0" size="0.025" rgba="0.1 0.3 0.9 1"/>
    </body>

    <body name="obstacle_0" pos="0.35 0.10 0.18" mocap="true">
      <geom name="obstacle_0_geom" type="sphere" size="0.06" rgba="0.8 0.2 0.2 1"/>
    </body>
    <body name="obstacle_1" pos="0.45 -0.12 0.2" mocap="true">
      <geom name="obstacle_1_geom" type="sphere" size="0.06" rgba="0.8 0.2 0.2 1"/>
    </body>
    <body name="obstacle_2" pos="0.25 0.18 0.12" mocap="true">
      <geom name="obstacle_2_geom" type="sphere" size="0.06" rgba="0.8 0.2 0.2 1"/>
    </body>
    <body name="obstacle_3" pos="0.42 0.2 0.16" mocap="true">
      <geom name="obstacle_3_geom" type="sphere" size="0.06" rgba="0.8 0.2 0.2 1"/>
    </body>
    <body name="obstacle_4" pos="0.30 -0.2 0.22" mocap="true">
      <geom name="obstacle_4_geom" type="sphere" size="0.06" rgba="0.8 0.2 0.2 1"/>
    </body>
  </worldbody>

  <actuator>
    <motor name="joint1_motor" joint="joint1" gear="35"/>
    <motor name="joint2_motor" joint="joint2" gear="30"/>
    <motor name="joint3_motor" joint="joint3" gear="25"/>
  </actuator>
</mujoco>
